ui_support.run_gb2fasta
Exception in Tkinter callback
Traceback (most recent call last):
  File "C:\Program Files\Python310\lib\tkinter\__init__.py", line 1921, in __call__
    return self.func(*args)
TypeError: open_file() missing 2 required positional arguments: 'title' and 'entry'
Exception in Tkinter callback
Traceback (most recent call last):
  File "C:\Program Files\Python310\lib\tkinter\__init__.py", line 1921, in __call__
    return self.func(*args)
TypeError: open_file() missing 2 required positional arguments: 'title' and 'entry'
